2025-10-16 23:55:36,402 INFO    MainThread:48956 [wandb_setup.py:_flush():81] Current SDK version is 0.22.2
2025-10-16 23:55:36,402 INFO    MainThread:48956 [wandb_setup.py:_flush():81] Configure stats pid to 48956
2025-10-16 23:55:36,402 INFO    MainThread:48956 [wandb_setup.py:_flush():81] Loading settings from C:\Users\himet\.config\wandb\settings
2025-10-16 23:55:36,402 INFO    MainThread:48956 [wandb_setup.py:_flush():81] Loading settings from D:\sem5 stuff\ComputerVision\pytorch-CycleGAN-and-pix2pix_CVPR-2017\wandb\settings
2025-10-16 23:55:36,402 INFO    MainThread:48956 [wandb_setup.py:_flush():81] Loading settings from environment variables
2025-10-16 23:55:36,402 INFO    MainThread:48956 [wandb_init.py:setup_run_log_directory():705] Logging user logs to D:\sem5 stuff\ComputerVision\pytorch-CycleGAN-and-pix2pix_CVPR-2017\wandb\run-20251016_235536-kw4n3bce\logs\debug.log
2025-10-16 23:55:36,403 INFO    MainThread:48956 [wandb_init.py:setup_run_log_directory():706] Logging internal logs to D:\sem5 stuff\ComputerVision\pytorch-CycleGAN-and-pix2pix_CVPR-2017\wandb\run-20251016_235536-kw4n3bce\logs\debug-internal.log
2025-10-16 23:55:36,403 INFO    MainThread:48956 [wandb_init.py:init():832] calling init triggers
2025-10-16 23:55:36,403 INFO    MainThread:48956 [wandb_init.py:init():837] wandb.init called with sweep_config: {}
config: {'dataroot': './datasets/maps', 'name': 'maps_pix2pix', 'checkpoints_dir': './checkpoints', 'model': 'pix2pix', 'input_nc': 3, 'output_nc': 3, 'ngf': 64, 'ndf': 64, 'netD': 'basic', 'netG': 'unet_256', 'n_layers_D': 3, 'norm': 'batch', 'init_type': 'normal', 'init_gain': 0.02, 'no_dropout': False, 'dataset_mode': 'aligned', 'direction': 'AtoB', 'serial_batches': False, 'num_threads': 4, 'batch_size': 1, 'load_size': 286, 'crop_size': 256, 'max_dataset_size': inf, 'preprocess': 'resize_and_crop', 'no_flip': False, 'display_winsize': 256, 'epoch': 'latest', 'load_iter': 0, 'verbose': False, 'suffix': '', 'use_wandb': True, 'wandb_project_name': 'CycleGAN-and-pix2pix', 'display_freq': 400, 'update_html_freq': 1000, 'print_freq': 100, 'no_html': False, 'save_latest_freq': 5000, 'save_epoch_freq': 5, 'save_by_iter': False, 'continue_train': False, 'epoch_count': 1, 'phase': 'train', 'n_epochs': 100, 'n_epochs_decay': 100, 'beta1': 0.5, 'lr': 0.0002, 'gan_mode': 'vanilla', 'pool_size': 0, 'lr_policy': 'linear', 'lr_decay_iters': 50, 'lambda_L1': 100.0, 'isTrain': True, 'device': device(type='cuda', index=0), '_wandb': {}}
2025-10-16 23:55:36,403 INFO    MainThread:48956 [wandb_init.py:init():880] starting backend
2025-10-16 23:55:39,762 INFO    MainThread:48956 [wandb_init.py:init():883] sending inform_init request
2025-10-16 23:55:39,791 INFO    MainThread:48956 [wandb_init.py:init():891] backend started and connected
2025-10-16 23:55:39,792 INFO    MainThread:48956 [wandb_init.py:init():961] updated telemetry
2025-10-16 23:55:39,792 INFO    MainThread:48956 [wandb_init.py:init():985] communicating run to backend with 90.0 second timeout
2025-10-16 23:55:45,902 INFO    MainThread:48956 [wandb_init.py:init():1036] starting run threads in backend
2025-10-16 23:55:46,586 INFO    MainThread:48956 [wandb_run.py:_console_start():2509] atexit reg
2025-10-16 23:55:46,586 INFO    MainThread:48956 [wandb_run.py:_redirect():2357] redirect: wrap_raw
2025-10-16 23:55:46,586 INFO    MainThread:48956 [wandb_run.py:_redirect():2426] Wrapping output streams.
2025-10-16 23:55:46,587 INFO    MainThread:48956 [wandb_run.py:_redirect():2449] Redirects installed.
2025-10-16 23:55:46,592 INFO    MainThread:48956 [wandb_init.py:init():1076] run started, returning control to user process
2025-10-17 03:28:23,568 INFO    wandb-AsyncioManager-main:48956 [service_client.py:_forward_responses():80] Reached EOF.
2025-10-17 03:28:23,570 INFO    wandb-AsyncioManager-main:48956 [mailbox.py:close():137] Closing mailbox, abandoning 1 handles.
2025-10-17 03:28:25,464 ERROR   MainThread:48956 [redirect.py:_on_write():664] [all runs] error in stdout callback
Traceback (most recent call last):
  File "D:\venv\pix2pix_env\lib\site-packages\wandb\sdk\lib\redirect.py", line 662, in _on_write
    cb(written_data)
  File "D:\venv\pix2pix_env\lib\site-packages\wandb\sdk\wandb_run.py", line 2430, in <lambda>
    lambda data: self._console_raw_callback("stdout", data),
  File "D:\venv\pix2pix_env\lib\site-packages\wandb\sdk\wandb_run.py", line 399, in wrapper
    return func(self, *args, **kwargs)
  File "D:\venv\pix2pix_env\lib\site-packages\wandb\sdk\wandb_run.py", line 457, in wrapper_fn
    return func(self, *args, **kwargs)
  File "D:\venv\pix2pix_env\lib\site-packages\wandb\sdk\wandb_run.py", line 1595, in _console_raw_callback
    self._backend.interface.publish_output_raw(name, data)
  File "D:\venv\pix2pix_env\lib\site-packages\wandb\sdk\interface\interface.py", line 802, in publish_output_raw
    self._publish_output_raw(o)
  File "D:\venv\pix2pix_env\lib\site-packages\wandb\sdk\interface\interface_shared.py", line 37, in _publish_output_raw
    self._publish(rec)
  File "D:\venv\pix2pix_env\lib\site-packages\wandb\sdk\interface\interface_sock.py", line 43, in _publish
    self._asyncer.run(lambda: self._client.publish(request))
  File "D:\venv\pix2pix_env\lib\site-packages\wandb\sdk\lib\asyncio_manager.py", line 136, in run
    return future.result()
  File "C:\Users\himet\AppData\Local\Programs\Python\Python310\lib\concurrent\futures\_base.py", line 445, in result
    return self.__get_result()
  File "C:\Users\himet\AppData\Local\Programs\Python\Python310\lib\concurrent\futures\_base.py", line 390, in __get_result
    raise self._exception
  File "D:\venv\pix2pix_env\lib\site-packages\wandb\sdk\lib\asyncio_manager.py", line 219, in _wrap
    return await fn()
  File "D:\venv\pix2pix_env\lib\site-packages\wandb\sdk\lib\service\service_client.py", line 38, in publish
    await self._send_server_request(request)
  File "D:\venv\pix2pix_env\lib\site-packages\wandb\sdk\lib\service\service_client.py", line 64, in _send_server_request
    await self._writer.drain()
  File "C:\Users\himet\AppData\Local\Programs\Python\Python310\lib\asyncio\streams.py", line 372, in drain
    await self._protocol._drain_helper()
  File "C:\Users\himet\AppData\Local\Programs\Python\Python310\lib\asyncio\streams.py", line 171, in _drain_helper
    raise ConnectionResetError('Connection lost')
ConnectionResetError: Connection lost
